Workbook
Name Slicer_Diabetes_Status: #N/A
Name Slicer_Weight_Status: #N/A

Sheet Medical_Examinations
A1: Customer ID | B1: BMI | C1: Weight Status | D1: HBA1C | E1: Diabetic Status | F1: Heart Issues | G1: Any Transplants | H1: Cancer history | I1: NumberOfMajorSurgeries | J1: smoker
A2: Id1 | B2: 47.41 | C2: {=_xlfn.IFS(Medical_Examinations!$B2>=30,"Obesity",Medical_Examinations!$B2>=25,"Overweight",Medical_Examinations!$B2>=18.5,"Normal Weight",TRUE,"Underweight")} -> Obesity | D2: 7.47 | E2: {=_xlfn.IFS(Medical_Examinations!$D2>6.5,"Diabetes",Medical_Examinations!$D2>5.7,"Prediabetes",TRUE,"Normal")} -> Diabetes | F2: No | G2: No | H2: No | I2: 0 | J2: yes
A3: Id2 | B3: 30.36 | C3: {=_xlfn.IFS(Medical_Examinations!$B3>=30,"Obesity",Medical_Examinations!$B3>=25,"Overweight",Medical_Examinations!$B3>=18.5,"Normal Weight",TRUE,"Underweight")} -> Obesity | D3: 5.77 | E3: {=_xlfn.IFS(Medical_Examinations!$D3>6.5,"Diabetes",Medical_Examinations!$D3>5.7,"Prediabetes",TRUE,"Normal")} -> Prediabetes | F3: No | G3: No | H3: No | I3: 0 | J3: yes
A4: Id3 | B4: 34.485 | C4: {=_xlfn.IFS(Medical_Examinations!$B4>=30,"Obesity",Medical_Examinations!$B4>=25,"Overweight",Medical_Examinations!$B4>=18.5,"Normal Weight",TRUE,"Underweight")} -> Obesity | D4: 11.87 | E4: {=_xlfn.IFS(Medical_Examinations!$D4>6.5,"Diabetes",Medical_Examinations!$D4>5.7,"Prediabetes",TRUE,"Normal")} -> Diabetes | F4: yes | G4: No | H4: No | I4: 2 | J4: yes
A5: Id4 | B5: 38.095 | C5: {=_xlfn.IFS(Medical_Examinations!$B5>=30,"Obesity",Medical_Examinations!$B5>=25,"Overweight",Medical_Examinations!$B5>=18.5,"Normal Weight",TRUE,"Underweight")} -> Obesity | D5: 6.05 | E5: {=_xlfn.IFS(Medical_Examinations!$D5>6.5,"Diabetes",Medical_Examinations!$D5>5.7,"Prediabetes",TRUE,"Normal")} -> Prediabetes | F5: No | G5: No | H5: No | I5: 0 | J5: yes
A6: Id5 | B6: 35.53 | C6: {=_xlfn.IFS(Medical_Examinations!$B6>=30,"Obesity",Medical_Examinations!$B6>=25,"Overweight",Medical_Examinations!$B6>=18.5,"Normal Weight",TRUE,"Underweight")} -> Obesity | D6: 5.45 | E6: {=_xlfn.IFS(Medical_Examinations!$D6>6.5,"Diabetes",Medical_Examinations!$D6>5.7,"Prediabetes",TRUE,"Normal")} -> Normal | F6: No | G6: No | H6: No | I6: 0 | J6: yes
A7: Id6 | B7: 32.8 | C7: {=_xlfn.IFS(Medical_Examinations!$B7>=30,"Obesity",Medical_Examinations!$B7>=25,"Overweight",Medical_Examinations!$B7>=18.5,"Normal Weight",TRUE,"Underweight")} -> Obesity | D7: 6.59 | E7: {=_xlfn.IFS(Medical_Examinations!$D7>6.5,"Diabetes",Medical_Examinations!$D7>5.7,"Prediabetes",TRUE,"Normal")} -> Diabetes | F7: No | G7: No | H7: No | I7: 0 | J7: yes
A8: Id7 | B8: 36.4 | C8: {=_xlfn.IFS(Medical_Examinations!$B8>=30,"Obesity",Medical_Examinations!$B8>=25,"Overweight",Medical_Examinations!$B8>=18.5,"Normal Weight",TRUE,"Underweight")} -> Obesity | D8: 6.07 | E8: {=_xlfn.IFS(Medical_Examinations!$D8>6.5,"Diabetes",Medical_Examinations!$D8>5.7,"Prediabetes",TRUE,"Normal")} -> Prediabetes | F8: No | G8: No | H8: No | I8: 0 | J8: yes
A9: Id8 | B9: 36.96 | C9: {=_xlfn.IFS(Medical_Examinations!$B9>=30,"Obesity",Medical_Examinations!$B9>=25,"Overweight",Medical_Examinations!$B9>=18.5,"Normal Weight",TRUE,"Underweight")} -> Obesity | D9: 7.93 | E9: {=_xlfn.IFS(Medical_Examinations!$D9>6.5,"Diabetes",Medical_Examinations!$D9>5.7,"Prediabetes",TRUE,"Normal")} -> Diabetes | F9: No | G9: No | H9: No | I9: 3 | J9: yes
A10: Id9 | B10: 41.14 | C10: {=_xlfn.IFS(Medical_Examinations!$B10>=30,"Obesity",Medical_Examinations!$B10>=25,"Overweight",Medical_Examinations!$B10>=18.5,"Normal Weight",TRUE,"Underweight")} -> Obesity | D10: 9.58 | E10: {=_xlfn.IFS(Medical_Examinations!$D10>6.5,"Diabetes",Medical_Examinations!$D10>5.7,"Prediabetes",TRUE,"Normal")} -> Diabetes | F10: yes | G10: No | H10: Yes | I10: 1 | J10: No
A11: Id10 | B11: 38.06 | C11: {=_xlfn.IFS(Medical_Examinations!$B11>=30,"Obesity",Medical_Examinations!$B11>=25,"Overweight",Medical_Examinations!$B11>=18.5,"Normal Weight",TRUE,"Underweight")} -> Obesity | D11: 10.79 | E11: {=_xlfn.IFS(Medical_Examinations!$D11>6.5,"Diabetes",Medical_Examinations!$D11>5.7,"Prediabetes",TRUE,"Normal")} -> Diabetes | F11: No | G11: No | H11: No | I11: 0 | J11: yes
A12: Id11 | B12: 37.7 | C12: {=_xlfn.IFS(Medical_Examinations!$B12>=30,"Obesity",Medical_Examinations!$B12>=25,"Overweight",Medical_Examinations!$B12>=18.5,"Normal Weight",TRUE,"Underweight")} -> Obesity | D12: 5.96 | E12: {=_xlfn.IFS(Medical_Examinations!$D12>6.5,"Diabetes",Medical_Examinations!$D12>5.7,"Prediabetes",TRUE,"Normal")} -> Prediabetes | F12: yes | G12: No | H12: No | I12: 2 | J12: yes
A13: Id12 | B13: 42.13 | C13: {=_xlfn.IFS(Medical_Examinations!$B13>=30,"Obesity",Medical_Examinations!$B13>=25,"Overweight",Medical_Examinations!$B13>=18.5,"Normal Weight",TRUE,"Underweight")} -> Obesity | D13: 11.9 | E13: {=_xlfn.IFS(Medical_Examinations!$D13>6.5,"Diabetes",Medical_Examinations!$D13>5.7,"Prediabetes",TRUE,"Normal")} -> Diabetes | F13: No | G13: No | H13: No | I13: 0 | J13: yes
... A2336: Id2335 | B2336: 17.58 | C2336: {=_xlfn.IFS(Medical_Examinations!$B2336>=30,"Obesity",Medical_Examinations!$B2336>=25,"Overweight",Medical_Examinations!$B2336>=18.5,"Normal Weight",TRUE,"Underweight")} -> Underweight | D2336: 4.51 | E2336: {=_xlfn.IFS(Medical_Examinations!$D2336>6.5,"Diabetes",Medical_Examinations!$D2336>5.7,"Prediabetes",TRUE,"Normal")} -> Normal | F2336: No | G2336: No | H2336: No | I2336: 1 | J2336: No

Sheet Customer Names
A1: Customer ID | B1: Name | C1: Title | D1: First Name | E1: Last Name
A2: Id1 | B2: Hawks, Ms. Kelly | C2: Ms | D2: Hawks | E2: Kelly
A3: Id2 | B3: Lehner, Mr. Matthew D | C3: Mr | D3: Lehner | E3: Matthew D
A4: Id3 | B4: Lu, Mr. Phil | C4: Mr | D4: Lu | E4: Phil
A5: Id4 | B5: Osborne, Ms. Kelsey | C5: Ms | D5: Osborne | E5: Kelsey
A6: Id5 | B6: Kadala, Ms. Kristyn | C6: Ms | D6: Kadala | E6: Kristyn
A7: Id6 | B7: Baker, Mr. Russell B. | C7: Mr | D7: Baker | E7: Russell B
A8: Id7 | B8: Macpherson, Mr. Scott | C8: Mr | D8: Macpherson | E8: Scott
A9: Id8 | B9: Hallman, Mr. Stephen | C9: Mr | D9: Hallman | E9: Stephen
A10: Id9 | B10: Moran, Mr. Patrick R. | C10: Mr | D10: Moran | E10: Patrick R
A11: Id10 | B11: Benner, Ms. Brooke N. | C11: Ms | D11: Benner | E11: Brooke N
A12: Id11 | B12: Fierro Vargas, Ms. Paola Andrea | C12: Ms | D12: Fierro Vargas | E12: Paola Andrea
... A2336: Id2335 | B2336: German, Mr. Aaron K | C2336: Mr | D2336: German | E2336: Aaron K

Sheet Hospitalization
A1: Customer ID | B1: year | C1: month | D1: date | E1: Date of Birth | F1: Age | G1: children | H1: charges | I1: Hospital tier | J1: City tier | K1: State ID
A2: Id1 | B2: 1968 | C2: Oct | D2: 12 | E2: 25123 | F2: =DATEDIF(Hospitalization!$E2344,TODAY(),"Y") -> 24 | G2: 0 | H2: 63770.43 | I2: tier - 1 | J2: tier - 3 | K2: R1013
A3: Id10 | B3: 1977 | C3: Jun | D3: 8 | E3: 28284 | F3: =DATEDIF(Hospitalization!$E2343,TODAY(),"Y") -> 28 | G3: 0 | H3: 62592.87 | I3: tier - 2 | J3: tier - 3 | K3: R1013
A4: Id100 | B4: 1970 | C4: Sep | D4: 11 | E4: 25822 | F4: =DATEDIF(Hospitalization!$E2342,TODAY(),"Y") -> 34 | G4: 3 | H4: 60021.4 | I4: tier - 1 | J4: tier - 1 | K4: R1012
A5: Id1000 | B5: 1991 | C5: Jun | D5: 6 | E5: 33395 | F5: =DATEDIF(Hospitalization!$E2341,TODAY(),"Y") -> 33 | G5: 1 | H5: 58571.07 | I5: tier - 1 | J5: tier - 3 | K5: R1024
A6: Id1001 | B6: 1989 | C6: Jun | D6: 19 | E6: 32678 | F6: =DATEDIF(Hospitalization!$E2340,TODAY(),"Y") -> 33 | G6: 0 | H6: 55135.4 | I6: tier - 1 | J6: tier - 2 | K6: R1012
A7: Id1002 | B7: 1962 | C7: Aug | D7: 4 | E7: 22862 | F7: =DATEDIF(Hospitalization!$E2339,TODAY(),"Y") -> 34 | G7: 0 | H7: 52590.83 | I7: tier - 1 | J7: tier - 3 | K7: R1011
A8: Id1003 | B8: 1994 | C8: Oct | D8: 27 | E8: 34634 | F8: =DATEDIF(Hospitalization!$E2338,TODAY(),"Y") -> 33 | G8: 1 | H8: 51194.56 | I8: tier - 1 | J8: tier - 3 | K8: R1011
A9: Id1004 | B9: 1958 | C9: Jun | D9: 27 | E9: 21363 | F9: =DATEDIF(Hospitalization!$E2337,TODAY(),"Y") -> 31 | G9: 2 | H9: 49577.66 | I9: tier - 2 | J9: tier - 2 | K9: R1013
A10: Id1005 | B10: 1963 | C10: Sep | D10: 4 | E10: 23258 | F10: =DATEDIF(Hospitalization!$E2336,TODAY(),"Y") -> 23 | G10: 1 | H10: 48970.25 | I10: tier - 1 | J10: tier - 2 | K10: R1013
A11: Id1006 | B11: 1978 | C11: Dec | D11: 29 | E11: 28853 | F11: =DATEDIF(Hospitalization!$E2335,TODAY(),"Y") -> 28 | G11: 0 | H11: 48885.14 | I11: tier - 1 | J11: tier - 2 | K11: R1013
A12: Id1007 | B12: 1959 | C12: Jul | D12: 22 | E12: 21753 | F12: =DATEDIF(Hospitalization!$E2334,TODAY(),"Y") -> 25 | G12: 0 | H12: 48824.45 | I12: tier - 2 | J12: tier - 1 | K12: R1011
A13: Id1008 | B13: 1965 | C13: Oct | D13: 27 | E13: 24042 | F13: =DATEDIF(Hospitalization!$E2333,TODAY(),"Y") -> 26 | G13: 1 | H13: 48675.52 | I13: tier - 1 | J13: tier - 2 | K13: R1013
A14: Id1009 | B14: 1962 | C14: Oct | D14: 11 | E14: 22930 | F14: =DATEDIF(Hospitalization!$E2332,TODAY(),"Y") -> 26 | G14: 0 | H14: 48673.56 | I14: tier - 1 | J14: tier - 2 | K14: R1013
A15: Id101 | B15: 1968 | C15: Dec | D15: 1 | E15: 25173 | F15: =DATEDIF(Hospitalization!$E2331,TODAY(),"Y") -> 24 | G15: 3 | H15: 48549.18 | I15: tier - 1 | J15: tier - 3 | K15: R1016
A16: Id1010 | B16: 1961 | C16: Dec | D16: 21 | E16: 22636 | F16: =DATEDIF(Hospitalization!$E2330,TODAY(),"Y") -> 33 | G16: 1 | H16: 48517.56 | I16: tier - 1 | J16: tier - 3 | K16: R1024
A17: Id1011 | B17: 1962 | C17: Aug | D17: 27 | E17: 22885 | F17: =DATEDIF(Hospitalization!$E2329,TODAY(),"Y") -> 29 | G17: 0 | H17: 48173.36 | I17: tier - 1 | J17: tier - 3 | K17: R1011
A18: Id1012 | B18: 1958 | C18: Nov | D18: 16 | E18: 21505 | F18: =DATEDIF(Hospitalization!$E2328,TODAY(),"Y") -> 33 | G18: 1 | H18: 47928.03 | I18: tier - 2 | J18: tier - 3 | K18: R1011
A19: Id1013 | B19: 1963 | C19: Aug | D19: 5 | E19: 23228 | F19: =DATEDIF(Hospitalization!$E2327,TODAY(),"Y") -> 30 | G19: 1 | H19: 47896.79 | I19: tier - 1 | J19: tier - 3 | K19: R1024
A20: Id1014 | B20: 1964 | C20: Nov | D20: 7 | E20: 23688 | F20: =DATEDIF(Hospitalization!$E2326,TODAY(),"Y") -> 30 | G20: 2 | H20: 47496.49 | I20: tier - 1 | J20: tier - 3 | K20: R1012
A21: Id1015 | B21: 1971 | C21: Sep | D21: 27 | E21: 26203 | F21: =DATEDIF(Hospitalization!$E2325,TODAY(),"Y") -> 22 | G21: 2 | H21: 47462.89 | I21: tier - 1 | J21: tier - 2 | K21: R1013
A22: Id1016 | B22: 1961 | C22: Jun | D22: 13 | E22: 22445 | F22: =DATEDIF(Hospitalization!$E2324,TODAY(),"Y") -> 25 | G22: 1 | H22: 47403.88 | I22: tier - 1 | J22: tier - 3 | K22: R1011
A23: Id1017 | B23: 1959 | C23: Oct | D23: 4 | E23: 21827 | F23: =DATEDIF(Hospitalization!$E2323,TODAY(),"Y") -> 32 | G23: 2 | H23: 47305.31 | I23: tier - 2 | J23: tier - 1 | K23: R1011
A24: Id1018 | B24: 1958 | C24: Sep | D24: 3 | E24: 21431 | F24: =DATEDIF(Hospitalization!$E2322,TODAY(),"Y") -> 31 | G24: 2 | H24: 47291.06 | I24: tier - 2 | J24: tier - 1 | K24: R1011
A25: Id1019 | B25: 1970 | C25: Dec | D25: 28 | E25: 25930 | F25: =DATEDIF(Hospitalization!$E2321,TODAY(),"Y") -> 30 | G25: 2 | H25: 47269.85 | I25: tier - 1 | J25: tier - 2 | K25: R1013
A26: Id102 | B26: 1959 | C26: Jul | D26: 14 | E26: 21745 | F26: =DATEDIF(Hospitalization!$E2320,TODAY(),"Y") -> 25 | G26: 0 | H26: 47055.53 | I26: tier - 2 | J26: tier - 1 | K26: R1013
A27: Id1020 | B27: 1958 | C27: Sep | D27: 15 | E27: 21443 | F27: =DATEDIF(Hospitalization!$E2319,TODAY(),"Y") -> 31 | G27: 0 | H27: 46889.26 | I27: tier - 2 | J27: tier - 3 | K27: R1013
A28: Id1021 | B28: 1960 | C28: Nov | D28: 17 | E28: 22237 | F28: =DATEDIF(Hospitalization!$E2318,TODAY(),"Y") -> 26 | G28: 3 | H28: 46718.16 | I28: tier - 1 | J28: tier - 1 | K28: R1012
A29: Id1022 | B29: 1969 | C29: Jun | D29: 23 | E29: 25377 | F29: =DATEDIF(Hospitalization!$E2317,TODAY(),"Y") -> 27 | G29: 3 | H29: 46661.44 | I29: tier - 1 | J29: tier - 3 | K29: R1012
A30: Id1023 | B30: 1961 | C30: Aug | D30: 8 | E30: 22501 | F30: =DATEDIF(Hospitalization!$E2316,TODAY(),"Y") -> 31 | G30: 0 | H30: 46599.11 | I30: tier - 1 | J30: tier - 1 | K30: R1013
A31: Id1024 | B31: 1971 | C31: Dec | D31: 6 | E31: 26273 | F31: =DATEDIF(Hospitalization!$E2315,TODAY(),"Y") -> 31 | G31: 3 | H31: 46255.11 | I31: tier - 1 | J31: tier - 3 | K31: R1024
A32: Id1025 | B32: 1978 | C32: Aug | D32: 17 | E32: 28719 | F32: =DATEDIF(Hospitalization!$E2314,TODAY(),"Y") -> 24 | G32: 2 | H32: 46200.99 | I32: tier - 1 | J32: tier - 1 | K32: R1013
A33: Id1026 | B33: 1976 | C33: Dec | D33: 2 | E33: 28096 | F33: =DATEDIF(Hospitalization!$E2313,TODAY(),"Y") -> 24 | G33: 3 | H33: 46151.12 | I33: tier - 1 | J33: tier - 3 | K33: R1013
A34: Id1027 | B34: 1962 | C34: Dec | D34: 4 | E34: 22984 | F34: =DATEDIF(Hospitalization!$E2312,TODAY(),"Y") -> 31 | G34: 3 | H34: 46130.53 | I34: tier - 1 | J34: tier - 1 | K34: R1012
A35: Id1028 | B35: 1985 | C35: Sep | D35: 30 | E35: 31320 | F35: =DATEDIF(Hospitalization!$E2311,TODAY(),"Y") -> 33 | G35: 2 | H35: 46113.51 | I35: tier - 2 | J35: tier - 3 | K35: R1011
A36: Id1029 | B36: 1979 | C36: Aug | D36: 12 | E36: 29079 | F36: =DATEDIF(Hospitalization!$E2310,TODAY(),"Y") -> 22 | G36: 0 | H36: 45863.21 | I36: tier - 2 | J36: tier - 1 | K36: R1013
A37: Id103 | B37: 1960 | C37: Dec | D37: 21 | E37: 22271 | F37: =DATEDIF(Hospitalization!$E2309,TODAY(),"Y") -> 29 | G37: 0 | H37: 45710.21 | I37: tier - 2 | J37: tier - 2 | K37: R1016
A38: Id1030 | B38: 1974 | C38: Aug | D38: 9 | E38: 27250 | F38: =DATEDIF(Hospitalization!$E2308,TODAY(),"Y") -> 27 | G38: 2 | H38: 45702.02 | I38: tier - 2 | J38: tier - 2 | K38: R1012
A39: Id1031 | B39: 1962 | C39: Dec | D39: 17 | E39: 22997 | F39: =DATEDIF(Hospitalization!$E2307,TODAY(),"Y") -> 24 | G39: 0 | H39: 45008.96 | I39: tier - 2 | J39: tier - 2 | K39: R1013
A40: Id1032 | B40: 1971 | C40: Aug | D40: 13 | E40: 26158 | F40: =DATEDIF(Hospitalization!$E2306,TODAY(),"Y") -> 21 | G40: 2 | H40: 44641.2 | I40: tier - 2 | J40: tier - 3 | K40: R1024
...

Sheet Pivot Table
E2: Major Surgeries With Transplants | F2: Average of HBA1C | H2: NumberOfMajorSurgeries | I2: Average of HBA1C
A3: Cancer History | B3: Count of Smoker | E3: 0 | F3: 6.7226249 | H3: 0 | I3: 6.7226249 | K3: Diabetics&WeightStatus | L3: Sum of Charges
A4: No | B4: 299 | E4: No | F4: 6.7317385 | H4: 1 | I4: 4.9593999 | K4: Diabetes | L4: 2219296.6
A5: Yes | B5: 54 | E5: Unknown | F5: 5.6305051 | H5: 2 | I5: 7.1488806 | K5: Normal Weight | L5: 2219296.6
A6: Grand Total | B6: 353 | E6: 1 | F6: 4.9593999 | H6: Grand Total | I6: 5.6305051 | K6: Grand Total | L6: 2219296.6
E7: No | F7: 4.93888
E8: yes | F8: 5.2206481
E9: 2 | F9: 7.1488806
E10: No | F10: 7.3594215
E11: yes | F11: 5.1892308
E12: Grand Total | F12: 5.6305051
Q15: Count of Smoker | R15: Count of BMI | S15: Count of HBA1C | T15: Average of Charges | U15: Sum of Charges
Q16: 353 | R16: 353 | S16: 353 | T16: 16503.201 | U16: 5825629.9
Q18: =GETPIVOTDATA("Count of Smoker",$Q$15) -> 353 | R18: =GETPIVOTDATA("Count of BMI",$Q$15) -> 353 | S18: =GETPIVOTDATA("Count of HBA1C",$Q$15) -> 353 | T18: =GETPIVOTDATA("Average of Charges",$Q$15) -> 16503.201 | U18: =GETPIVOTDATA("Sum of Charges",$Q$15) -> 5825629.9
A22: Age | B22: Count of BMI | C22: Count of HBA1C | H22: State &Hospital | I22: Average of Charges
A23: 21 | B23: 37 | C23: 37 | H23: R1011 | I23: 22011.153
A24: 22 | B24: 90 | C24: 90 | H24: tier - 1 | I24: 29872.376
A25: 23 | B25: 72 | C25: 72 | H25: tier - 2 | I25: 22845.698
A26: 24 | B26: 55 | C26: 55 | H26: tier - 3 | I26: 11186.24
A27: 25 | B27: 55 | C27: 55 | H27: R1012 | I27: 15213.039
A28: 26 | B28: 47 | C28: 47 | H28: tier - 1 | I28: 23698.949 | Q28: Count of Any Transplants | R28: Count of Heart Issues | S28: Count of Cancer history
A29: 27 | B29: 45 | C29: 45 | H29: tier - 2 | I29: 14503.088 | Q29: 2342 | R29: 2342 | S29: 2342
A30: 28 | B30: 56 | C30: 56 | H30: tier - 3 | I30: 11551.663
A31: 29 | B31: 48 | C31: 48 | H31: R1013 | I31: 15853.41 | S31: =GETPIVOTDATA("Count of Cancer history",$Q$28) -> 2342
A32: 30 | B32: 47 | C32: 47 | H32: tier - 1 | I32: 25725.512
A33: 31 | B33: 55 | C33: 55 | H33: tier - 2 | I33: 16045.642
A34: 32 | B34: 54 | C34: 54 | H34: tier - 3 | I34: 11509.001
A35: 33 | B35: 45 | C35: 45 | H35: R1014 | I35: 21880.82
A36: 34 | B36: 63 | C36: 63 | H36: tier - 3 | I36: 21880.82 | K36: Age | L36: Average of Charges
A37: 35 | B37: 49 | C37: 49 | H37: R1016 | I37: 11733.995 | K37: 21 | L37: 36765.972
A38: 36 | B38: 51 | C38: 51 | H38: tier - 1 | I38: 19798.05 | K38: 22 | L38: 30396.308
A39: 37 | B39: 46 | C39: 46 | H39: tier - 2 | I39: 10854.734 | K39: 23 | L39: 26363.815
A40: 38 | B40: 51 | C40: 51 | H40: tier - 3 | I40: 10817.057 | K40: 24 | L40: 28591.498
A41: 39 | B41: 44 | C41: 44 | H41: R1017 | I41: 18237.74 | K41: 25 | L41: 31538.39
A42: 40 | B42: 50 | C42: 50 | H42: tier - 2 | I42: 18237.74 | K42: 26 | L42: 29143.9
A43: 41 | B43: 37 | C43: 37 | H43: R1019 | I43: 15940.455 | K43: 27 | L43: 24053.837
A44: 42 | B44: 54 | C44: 54 | H44: tier - 1 | I44: 18157.88 | K44: 28 | L44: 32555.065
A45: 43 | B45: 51 | C45: 51 | H45: tier - 2 | I45: 21882.4 | K45: 29 | L45: 26851.226
A46: 44 | B46: 46 | C46: 46 | H46: tier - 3 | I46: 11860.77 | K46: 30 | L46: 24281.307
A47: 45 | B47: 49 | C47: 49 | H47: R1021 | I47: 11451.922 | K47: 31 | L47: 27982.144
...

Sheet Dashboard

Sheet HealthCare
A1: Customer ID | B1: Title | C1: First Name | D1: BMI | E1: HBA1C | F1: Heart Issues | G1: Any Transplants | H1: Cancer history | I1: NumberOfMajorSurgeries | J1: Smoker | K1: Weight Status | L1: Diabetes Status | M1: Date of Birth | N1: Age | O1: State ID | P1: City Tier | Q1: Charges | R1: Hospital Tier
A2: Id1 | B2: =VLOOKUP(A2,'Customer Names'!A2:E1320,3,TRUE) -> Ms | C2: =VLOOKUP(A2,'Customer Names'!A2:E2336,4,TRUE) -> Hawks | D2: =VLOOKUP(HealthCare!A2,Medical_Examinations!A1:J2336,2,TRUE) -> 47.41 | E2: =VLOOKUP(HealthCare!A2,Medical_Examinations!A1:J2336,4,TRUE) -> 7.47 | F2: =VLOOKUP(A2,Medical_Examinations!A1:J2336,6,TRUE) -> No | G2: =VLOOKUP(A2,Medical_Examinations!A1:J2336,7,TRUE) -> No | H2: =VLOOKUP(A2,Medical_Examinations!A1:J2336,8,TRUE) -> No | I2: =VLOOKUP(A2,Medical_Examinations!A1:J2336,9,TRUE) -> 0 | J2: =VLOOKUP(A2,Medical_Examinations!A1:J2336,10,TRUE) -> yes | K2: =VLOOKUP(A2,Medical_Examinations!A1:J2336,3,TRUE) -> Obesity | L2: =VLOOKUP(A2,Medical_Examinations!A1:J2336,5,TRUE) -> Diabetes | M2: =VLOOKUP(A2,Hospitalization!A2:K2344,5,FALSE) -> 25123 | N2: =VLOOKUP(A2,Hospitalization!A2:K2344,6,FALSE) -> 24 | O2: =VLOOKUP(A2,Hospitalization!A2:K2344,11) -> R1013 | P2: =VLOOKUP(A2,Hospitalization!A2:K2344,10,TRUE) -> tier - 3 | Q2: =VLOOKUP(A2,Hospitalization!A2:K2344,8,TRUE) -> 63770.43 | R2: =VLOOKUP(HealthCare!A2,Hospitalization!A2:K2344,9,TRUE) -> tier - 1
A3: Id2 | B3: =VLOOKUP(A3,'Customer Names'!A3:E1321,3,TRUE) -> Ms | C3: =VLOOKUP(A3,'Customer Names'!A1:E826,4,FALSE) -> Lehner | D3: =VLOOKUP(HealthCare!A3,Medical_Examinations!A2:J2337,2,TRUE) -> 40.185 | E3: =VLOOKUP(HealthCare!A3,Medical_Examinations!A2:J2337,4,TRUE) -> 5.88 | F3: =VLOOKUP(A3,Medical_Examinations!A2:J2337,6,TRUE) -> yes | G3: =VLOOKUP(A3,Medical_Examinations!A2:J2337,7,TRUE) -> No | H3: =VLOOKUP(A3,Medical_Examinations!A2:J2337,8,TRUE) -> No | I3: =VLOOKUP(A3,Medical_Examinations!A2:J2337,9,TRUE) -> 0 | J3: =VLOOKUP(A3,Medical_Examinations!A2:J2337,10,TRUE) -> No | K3: =VLOOKUP(A3,Medical_Examinations!A2:J2337,3,TRUE) -> Obesity | L3: =VLOOKUP(A3,Medical_Examinations!A2:J2337,5,TRUE) -> Prediabetes | M3: =VLOOKUP(A3,Hospitalization!A3:K2345,5,FALSE) -> 24741 | N3: =VLOOKUP(A3,Hospitalization!A3:K2345,6,FALSE) -> 43 | O3: =VLOOKUP(A3,Hospitalization!A3:K2345,11) -> R1011 | P3: =VLOOKUP(A3,Hospitalization!A3:K2345,10,TRUE) -> tier - 2 | Q3: =VLOOKUP(A3,Hospitalization!A3:K2345,8,TRUE) -> 10214.64 | R3: =VLOOKUP(HealthCare!A3,Hospitalization!A3:K2345,9,TRUE) -> tier - 3
A4: Id3 | B4: =VLOOKUP(A4,'Customer Names'!A4:E1322,3,TRUE) -> Mr | C4: =VLOOKUP(A4,'Customer Names'!A2:E827,4,FALSE) -> Lu | D4: =VLOOKUP(HealthCare!A4,Medical_Examinations!A3:J2338,2,TRUE) -> 17.58 | E4: =VLOOKUP(HealthCare!A4,Medical_Examinations!A3:J2338,4,TRUE) -> 4.51 | F4: =VLOOKUP(A4,Medical_Examinations!A3:J2338,6,TRUE) -> No | G4: =VLOOKUP(A4,Medical_Examinations!A3:J2338,7,TRUE) -> No | H4: =VLOOKUP(A4,Medical_Examinations!A3:J2338,8,TRUE) -> No | I4: =VLOOKUP(A4,Medical_Examinations!A3:J2338,9,TRUE) -> 1 | J4: =VLOOKUP(A4,Medical_Examinations!A3:J2338,10,TRUE) -> No | K4: =VLOOKUP(A4,Medical_Examinations!A3:J2338,3,TRUE) -> Underweight | L4: =VLOOKUP(A4,Medical_Examinations!A3:J2338,5,TRUE) -> Normal | M4: =VLOOKUP(A4,Hospitalization!A4:K2346,5,FALSE) -> 28056 | N4: =VLOOKUP(A4,Hospitalization!A4:K2346,6,FALSE) -> 65 | O4: =VLOOKUP(A4,Hospitalization!A4:K2346,11) -> R1013 | P4: =VLOOKUP(A4,Hospitalization!A4:K2346,10,TRUE) -> tier - 1 | Q4: =VLOOKUP(A4,Hospitalization!A4:K2346,8,TRUE) -> 6529.21 | R4: =VLOOKUP(HealthCare!A4,Hospitalization!A4:K2346,9,TRUE) -> tier - 2
A5: Id4 | B5: =VLOOKUP(A5,'Customer Names'!A5:E1323,3,TRUE) -> Ms | C5: =VLOOKUP(A5,'Customer Names'!A3:E828,4,FALSE) -> Osborne | D5: =VLOOKUP(HealthCare!A5,Medical_Examinations!A4:J2339,2,TRUE) -> 17.58 | E5: =VLOOKUP(HealthCare!A5,Medical_Examinations!A4:J2339,4,TRUE) -> 4.51 | F5: =VLOOKUP(A5,Medical_Examinations!A4:J2339,6,TRUE) -> No | G5: =VLOOKUP(A5,Medical_Examinations!A4:J2339,7,TRUE) -> No | H5: =VLOOKUP(A5,Medical_Examinations!A4:J2339,8,TRUE) -> No | I5: =VLOOKUP(A5,Medical_Examinations!A4:J2339,9,TRUE) -> 1 | J5: =VLOOKUP(A5,Medical_Examinations!A4:J2339,10,TRUE) -> No | K5: =VLOOKUP(A5,Medical_Examinations!A4:J2339,3,TRUE) -> Underweight | L5: =VLOOKUP(A5,Medical_Examinations!A4:J2339,5,TRUE) -> Normal | M5: =VLOOKUP(A5,Hospitalization!A5:K2347,5,FALSE) -> 34130 | N5: =VLOOKUP(A5,Hospitalization!A5:K2347,6,FALSE) -> 45 | O5: =VLOOKUP(A5,Hospitalization!A5:K2347,11) -> R1021 | P5: =VLOOKUP(A5,Hospitalization!A5:K2347,10,TRUE) -> tier - 1 | Q5: =VLOOKUP(A5,Hospitalization!A5:K2347,8,TRUE) -> 5748.13 | R5: =VLOOKUP(HealthCare!A5,Hospitalization!A5:K2347,9,TRUE) -> tier - 2
A6: Id5 | B6: =VLOOKUP(A6,'Customer Names'!A6:E1324,3,TRUE) -> Ms | C6: =VLOOKUP(A6,'Customer Names'!A4:E829,4,FALSE) -> Kadala | D6: =VLOOKUP(HealthCare!A6,Medical_Examinations!A5:J2340,2,TRUE) -> 17.58 | E6: =VLOOKUP(HealthCare!A6,Medical_Examinations!A5:J2340,4,TRUE) -> 4.51 | F6: =VLOOKUP(A6,Medical_Examinations!A5:J2340,6,TRUE) -> No | G6: =VLOOKUP(A6,Medical_Examinations!A5:J2340,7,TRUE) -> No | H6: =VLOOKUP(A6,Medical_Examinations!A5:J2340,8,TRUE) -> No | I6: =VLOOKUP(A6,Medical_Examinations!A5:J2340,9,TRUE) -> 1 | J6: =VLOOKUP(A6,Medical_Examinations!A5:J2340,10,TRUE) -> No | K6: =VLOOKUP(A6,Medical_Examinations!A5:J2340,3,TRUE) -> Underweight | L6: =VLOOKUP(A6,Medical_Examinations!A5:J2340,5,TRUE) -> Normal | M6: =VLOOKUP(A6,Hospitalization!A6:K2348,5,FALSE) -> 32409 | N6: =VLOOKUP(A6,Hospitalization!A6:K2348,6,FALSE) -> 62 | O6: =VLOOKUP(A6,Hospitalization!A6:K2348,11) -> R1012 | P6: =VLOOKUP(A6,Hospitalization!A6:K2348,10,TRUE) -> tier - 3 | Q6: =VLOOKUP(A6,Hospitalization!A6:K2348,8,TRUE) -> 4894.75 | R6: =VLOOKUP(HealthCare!A6,Hospitalization!A6:K2348,9,TRUE) -> tier - 3
A7: Id6 | B7: =VLOOKUP(A7,'Customer Names'!A7:E1325,3,TRUE) -> Ms | C7: =VLOOKUP(A7,'Customer Names'!A5:E830,4,FALSE) -> Baker | D7: =VLOOKUP(HealthCare!A7,Medical_Examinations!A6:J2341,2,TRUE) -> 17.58 | E7: =VLOOKUP(HealthCare!A7,Medical_Examinations!A6:J2341,4,TRUE) -> 4.51 | F7: =VLOOKUP(A7,Medical_Examinations!A6:J2341,6,TRUE) -> No | G7: =VLOOKUP(A7,Medical_Examinations!A6:J2341,7,TRUE) -> No | H7: =VLOOKUP(A7,Medical_Examinations!A6:J2341,8,TRUE) -> No | I7: =VLOOKUP(A7,Medical_Examinations!A6:J2341,9,TRUE) -> 1 | J7: =VLOOKUP(A7,Medical_Examinations!A6:J2341,10,TRUE) -> No | K7: =VLOOKUP(A7,Medical_Examinations!A6:J2341,3,TRUE) -> Underweight | L7: =VLOOKUP(A7,Medical_Examinations!A6:J2341,5,TRUE) -> Normal | M7: =VLOOKUP(A7,Hospitalization!A7:K2349,5,FALSE) -> 33208 | N7: =VLOOKUP(A7,Hospitalization!A7:K2349,6,FALSE) -> 23 | O7: =VLOOKUP(A7,Hospitalization!A7:K2349,11) -> R1013 | P7: =VLOOKUP(A7,Hospitalization!A7:K2349,10,TRUE) -> tier - 2 | Q7: =VLOOKUP(A7,Hospitalization!A7:K2349,8,TRUE) -> 4074.45 | R7: =VLOOKUP(HealthCare!A7,Hospitalization!A7:K2349,9,TRUE) -> tier - 3
A8: Id7 | B8: =VLOOKUP(A8,'Customer Names'!A8:E1326,3,TRUE) -> Ms | C8: =VLOOKUP(A8,'Customer Names'!A6:E831,4,FALSE) -> Macpherson | D8: =VLOOKUP(HealthCare!A8,Medical_Examinations!A7:J2342,2,TRUE) -> 17.58 | E8: =VLOOKUP(HealthCare!A8,Medical_Examinations!A7:J2342,4,TRUE) -> 4.51 | F8: =VLOOKUP(A8,Medical_Examinations!A7:J2342,6,TRUE) -> No | G8: =VLOOKUP(A8,Medical_Examinations!A7:J2342,7,TRUE) -> No | H8: =VLOOKUP(A8,Medical_Examinations!A7:J2342,8,TRUE) -> No | I8: =VLOOKUP(A8,Medical_Examinations!A7:J2342,9,TRUE) -> 1 | J8: =VLOOKUP(A8,Medical_Examinations!A7:J2342,10,TRUE) -> No | K8: =VLOOKUP(A8,Medical_Examinations!A7:J2342,3,TRUE) -> Underweight | L8: =VLOOKUP(A8,Medical_Examinations!A7:J2342,5,TRUE) -> Normal | M8: =VLOOKUP(A8,Hospitalization!A8:K2350,5,FALSE) -> 35349 | N8: =VLOOKUP(A8,Hospitalization!A8:K2350,6,FALSE) -> 66 | O8: =VLOOKUP(A8,Hospitalization!A8:K2350,11) -> R1012 | P8: =VLOOKUP(A8,Hospitalization!A8:K2350,10,TRUE) -> tier - 3 | Q8: =VLOOKUP(A8,Hospitalization!A8:K2350,8,TRUE) -> 3201.25 | R8: =VLOOKUP(HealthCare!A8,Hospitalization!A8:K2350,9,TRUE) -> tier - 2
A9: Id8 | B9: =VLOOKUP(A9,'Customer Names'!A9:E1327,3,TRUE) -> Ms | C9: =VLOOKUP(A9,'Customer Names'!A7:E832,4,FALSE) -> Hallman | D9: =VLOOKUP(HealthCare!A9,Medical_Examinations!A8:J2343,2,TRUE) -> 17.58 | E9: =VLOOKUP(HealthCare!A9,Medical_Examinations!A8:J2343,4,TRUE) -> 4.51 | F9: =VLOOKUP(A9,Medical_Examinations!A8:J2343,6,TRUE) -> No | G9: =VLOOKUP(A9,Medical_Examinations!A8:J2343,7,TRUE) -> No | H9: =VLOOKUP(A9,Medical_Examinations!A8:J2343,8,TRUE) -> No | I9: =VLOOKUP(A9,Medical_Examinations!A8:J2343,9,TRUE) -> 1 | J9: =VLOOKUP(A9,Medical_Examinations!A8:J2343,10,TRUE) -> No | K9: =VLOOKUP(A9,Medical_Examinations!A8:J2343,3,TRUE) -> Underweight | L9: =VLOOKUP(A9,Medical_Examinations!A8:J2343,5,TRUE) -> Normal | M9: =VLOOKUP(A9,Hospitalization!A9:K2351,5,FALSE) -> 38195 | N9: =VLOOKUP(A9,Hospitalization!A9:K2351,6,FALSE) -> 44 | O9: =VLOOKUP(A9,Hospitalization!A9:K2351,11) -> R1024 | P9: =VLOOKUP(A9,Hospitalization!A9:K2351,10,TRUE) -> tier - 2 | Q9: =VLOOKUP(A9,Hospitalization!A9:K2351,8,TRUE) -> 2211.13 | R9: =VLOOKUP(HealthCare!A9,Hospitalization!A9:K2351,9,TRUE) -> tier - 2
A10: Id9 | B10: =VLOOKUP(A10,'Customer Names'!A10:E1328,3,TRUE) -> Mr | C10: =VLOOKUP(A10,'Customer Names'!A8:E833,4,FALSE) -> Moran | D10: =VLOOKUP(HealthCare!A10,Medical_Examinations!A9:J2344,2,TRUE) -> 17.58 | E10: =VLOOKUP(HealthCare!A10,Medical_Examinations!A9:J2344,4,TRUE) -> 4.51 | F10: =VLOOKUP(A10,Medical_Examinations!A9:J2344,6,TRUE) -> No | G10: =VLOOKUP(A10,Medical_Examinations!A9:J2344,7,TRUE) -> No | H10: =VLOOKUP(A10,Medical_Examinations!A9:J2344,8,TRUE) -> No | I10: =VLOOKUP(A10,Medical_Examinations!A9:J2344,9,TRUE) -> 1 | J10: =VLOOKUP(A10,Medical_Examinations!A9:J2344,10,TRUE) -> No | K10: =VLOOKUP(A10,Medical_Examinations!A9:J2344,3,TRUE) -> Underweight | L10: =VLOOKUP(A10,Medical_Examinations!A9:J2344,5,TRUE) -> Normal | M10: =VLOOKUP(A10,Hospitalization!A10:K2352,5,FALSE) -> 33869 | N10: =VLOOKUP(A10,Hospitalization!A10:K2352,6,FALSE) -> 23 | O10: =VLOOKUP(A10,Hospitalization!A10:K2352,11) -> R1013 | P10: =VLOOKUP(A10,Hospitalization!A10:K2352,10,TRUE) -> tier - 1 | Q10: =VLOOKUP(A10,Hospitalization!A10:K2352,8,TRUE) -> 1566.88 | R10: =VLOOKUP(HealthCare!A10,Hospitalization!A10:K2352,9,TRUE) -> tier - 2
A11: Id10 | B11: =VLOOKUP(A11,'Customer Names'!A11:E1329,3,TRUE) -> Ms | C11: =VLOOKUP(A11,'Customer Names'!A9:E834,4,FALSE) -> Benner | D11: =VLOOKUP(HealthCare!A11,Medical_Examinations!A10:J2345,2,TRUE) -> 38.06 | E11: =VLOOKUP(HealthCare!A11,Medical_Examinations!A10:J2345,4,TRUE) -> 10.79 | F11: =VLOOKUP(A11,Medical_Examinations!A10:J2345,6,TRUE) -> No | G11: =VLOOKUP(A11,Medical_Examinations!A10:J2345,7,TRUE) -> No | H11: =VLOOKUP(A11,Medical_Examinations!A10:J2345,8,TRUE) -> No | I11: =VLOOKUP(A11,Medical_Examinations!A10:J2345,9,TRUE) -> 0 | J11: =VLOOKUP(A11,Medical_Examinations!A10:J2345,10,TRUE) -> yes | K11: =VLOOKUP(A11,Medical_Examinations!A10:J2345,3,TRUE) -> Obesity | L11: =VLOOKUP(A11,Medical_Examinations!A10:J2345,5,TRUE) -> Diabetes | M11: =VLOOKUP(A11,Hospitalization!A2:K2344,5,TRUE) -> 28284 | N11: =VLOOKUP(A11,Hospitalization!A2:K2344,6,FALSE) -> 28 | O11: =VLOOKUP(A2,Hospitalization!A2:K2344,11,FALSE) -> R1013 | P11: =VLOOKUP(A11,Hospitalization!A2:K2344,10,TRUE) -> tier - 3 | Q11: =VLOOKUP(A11,Hospitalization!A2:K2344,8,TRUE) -> 62592.87 | R11: =VLOOKUP(A11,Hospitalization!A2:K2344,9,TRUE) -> tier - 2
A12: Id11 | B12: =VLOOKUP(A12,'Customer Names'!A12:E1330,3,TRUE) -> Ms | C12: =VLOOKUP(A12,'Customer Names'!A10:E835,4,FALSE) -> Fierro Vargas | D12: =VLOOKUP(HealthCare!A12,Medical_Examinations!A11:J2346,2,TRUE) -> 37.7 | E12: =VLOOKUP(HealthCare!A12,Medical_Examinations!A11:J2346,4,TRUE) -> 5.96 | F12: =VLOOKUP(A12,Medical_Examinations!A11:J2346,6,TRUE) -> yes | G12: =VLOOKUP(A12,Medical_Examinations!A11:J2346,7,TRUE) -> No | H12: =VLOOKUP(A12,Medical_Examinations!A11:J2346,8,TRUE) -> No | I12: =VLOOKUP(A12,Medical_Examinations!A11:J2346,9,TRUE) -> 2 | J12: =VLOOKUP(A12,Medical_Examinations!A11:J2346,10,TRUE) -> yes | K12: =VLOOKUP(A12,Medical_Examinations!A11:J2346,3,TRUE) -> Obesity | L12: =VLOOKUP(A12,Medical_Examinations!A11:J2346,5,TRUE) -> Prediabetes | M12: =VLOOKUP(A12,Hospitalization!A12:K2354,5,FALSE) -> 31245 | N12: =VLOOKUP(A12,Hospitalization!A12:K2354,6,FALSE) -> 25 | O12: =VLOOKUP(A3,Hospitalization!A3:K2345,11,FALSE) -> R1011 | P12: =VLOOKUP(A12,Hospitalization!A12:K2354,10,TRUE) -> tier - 1 | Q12: =VLOOKUP(A12,Hospitalization!A12:K2354,8,TRUE) -> 39836.52 | R12: =VLOOKUP(HealthCare!A12,Hospitalization!A12:K2354,9,TRUE) -> tier - 2
A13: Id12 | B13: =VLOOKUP(A13,'Customer Names'!A13:E1331,3,TRUE) -> Mr | C13: =VLOOKUP(A13,'Customer Names'!A11:E836,4,FALSE) -> Franz | D13: =VLOOKUP(HealthCare!A13,Medical_Examinations!A12:J2347,2,TRUE) -> 35.97 | E13: =VLOOKUP(HealthCare!A13,Medical_Examinations!A12:J2347,4,TRUE) -> 8.13 | F13: =VLOOKUP(A13,Medical_Examinations!A12:J2347,6,TRUE) -> No | G13: =VLOOKUP(A13,Medical_Examinations!A12:J2347,7,TRUE) -> No | H13: =VLOOKUP(A13,Medical_Examinations!A12:J2347,8,TRUE) -> No | I13: =VLOOKUP(A13,Medical_Examinations!A12:J2347,9,TRUE) -> 0 | J13: =VLOOKUP(A13,Medical_Examinations!A12:J2347,10,TRUE) -> No | K13: =VLOOKUP(A13,Medical_Examinations!A12:J2347,3,TRUE) -> Obesity | L13: =VLOOKUP(A13,Medical_Examinations!A12:J2347,5,TRUE) -> Diabetes | M13: =VLOOKUP(A13,Hospitalization!A13:K2355,5,FALSE) -> 24836 | N13: =VLOOKUP(A13,Hospitalization!A13:K2355,6,FALSE) -> 22 | O13: =VLOOKUP(A4,Hospitalization!A4:K2346,11,FALSE) -> R1013 | P13: =VLOOKUP(A13,Hospitalization!A13:K2355,10,TRUE) -> tier - 2 | Q13: =VLOOKUP(A13,Hospitalization!A13:K2355,8,TRUE) -> 35160.13 | R13: =VLOOKUP(HealthCare!A13,Hospitalization!A13:K2355,9,TRUE) -> tier - 2
A14: Id13 | B14: =VLOOKUP(A14,'Customer Names'!A14:E1332,3,TRUE) -> Mr | C14: =VLOOKUP(A14,'Customer Names'!A12:E837,4,FALSE) -> Foster | D14: =VLOOKUP(HealthCare!A14,Medical_Examinations!A13:J2348,2,TRUE) -> 20.75 | E14: =VLOOKUP(HealthCare!A14,Medical_Examinations!A13:J2348,4,TRUE) -> 5.18 | F14: =VLOOKUP(A14,Medical_Examinations!A13:J2348,6,TRUE) -> yes | G14: =VLOOKUP(A14,Medical_Examinations!A13:J2348,7,TRUE) -> No | H14: =VLOOKUP(A14,Medical_Examinations!A13:J2348,8,TRUE) -> No | I14: =VLOOKUP(A14,Medical_Examinations!A13:J2348,9,TRUE) -> 2 | J14: =VLOOKUP(A14,Medical_Examinations!A13:J2348,10,TRUE) -> No | K14: =VLOOKUP(A14,Medical_Examinations!A13:J2348,3,TRUE) -> Normal Weight | L14: =VLOOKUP(A14,Medical_Examinations!A13:J2348,5,TRUE) -> Normal | M14: =VLOOKUP(A14,Hospitalization!A14:K2356,5,FALSE) -> 35966 | N14: =VLOOKUP(A14,Hospitalization!A14:K2356,6,FALSE) -> 30 | O14: =VLOOKUP(A5,Hospitalization!A5:K2347,11,FALSE) -> R1021 | P14: =VLOOKUP(A14,Hospitalization!A14:K2356,10,TRUE) -> tier - 2 | Q14: =VLOOKUP(A14,Hospitalization!A14:K2356,8,TRUE) -> 29760.6 | R14: =VLOOKUP(HealthCare!A14,Hospitalization!A14:K2356,9,TRUE) -> tier - 1
A15: Id14 | B15: =VLOOKUP(A15,'Customer Names'!A15:E1333,3,TRUE) -> Mr | C15: =VLOOKUP(A15,'Customer Names'!A13:E838,4,FALSE) -> Tenorio | D15: =VLOOKUP(HealthCare!A15,Medical_Examinations!A14:J2349,2,TRUE) -> 29.48 | E15: =VLOOKUP(HealthCare!A15,Medical_Examinations!A14:J2349,4,TRUE) -> 4.91 | F15: =VLOOKUP(A15,Medical_Examinations!A14:J2349,6,TRUE) -> No | G15: =VLOOKUP(A15,Medical_Examinations!A14:J2349,7,TRUE) -> No | H15: =VLOOKUP(A15,Medical_Examinations!A14:J2349,8,TRUE) -> No | I15: =VLOOKUP(A15,Medical_Examinations!A14:J2349,9,TRUE) -> 0 | J15: =VLOOKUP(A15,Medical_Examinations!A14:J2349,10,TRUE) -> No | K15: =VLOOKUP(A15,Medical_Examinations!A14:J2349,3,TRUE) -> Overweight | L15: =VLOOKUP(A15,Medical_Examinations!A14:J2349,5,TRUE) -> Normal | M15: =VLOOKUP(A15,Hospitalization!A15:K2357,5,FALSE) -> 35649 | N15: =VLOOKUP(A15,Hospitalization!A15:K2357,6,FALSE) -> 33 | O15: =VLOOKUP(A6,Hospitalization!A6:K2348,11,FALSE) -> R1012 | P15: =VLOOKUP(A15,Hospitalization!A15:K2357,10,TRUE) -> tier - 3 | Q15: =VLOOKUP(A15,Hospitalization!A15:K2357,8,TRUE) -> 23241.47 | R15: =VLOOKUP(HealthCare!A15,Hospitalization!A15:K2357,9,TRUE) -> tier - 2
A16: Id15 | B16: =VLOOKUP(A16,'Customer Names'!A16:E1334,3,TRUE) -> Ms | C16: =VLOOKUP(A16,'Customer Names'!A14:E839,4,FALSE) -> Rios | D16: =VLOOKUP(HealthCare!A16,Medical_Examinations!A15:J2350,2,TRUE) -> 22.58 | E16: =VLOOKUP(HealthCare!A16,Medical_Examinations!A15:J2350,4,TRUE) -> 7.46 | F16: =VLOOKUP(A16,Medical_Examinations!A15:J2350,6,TRUE) -> No | G16: =VLOOKUP(A16,Medical_Examinations!A15:J2350,7,TRUE) -> No | H16: =VLOOKUP(A16,Medical_Examinations!A15:J2350,8,TRUE) -> No | I16: =VLOOKUP(A16,Medical_Examinations!A15:J2350,9,TRUE) -> 0 | J16: =VLOOKUP(A16,Medical_Examinations!A15:J2350,10,TRUE) -> No | K16: =VLOOKUP(A16,Medical_Examinations!A15:J2350,3,TRUE) -> Normal Weight | L16: =VLOOKUP(A16,Medical_Examinations!A15:J2350,5,TRUE) -> Diabetes | M16: =VLOOKUP(A16,Hospitalization!A16:K2358,5,FALSE) -> 32846 | N16: =VLOOKUP(A16,Hospitalization!A16:K2358,6,FALSE) -> 39 | O16: =VLOOKUP(A7,Hospitalization!A7:K2349,11,FALSE) -> R1013 | P16: =VLOOKUP(A16,Hospitalization!A16:K2358,10,TRUE) -> tier - 2 | Q16: =VLOOKUP(A16,Hospitalization!A16:K2358,8,TRUE) -> 17904.53 | R16: =VLOOKUP(HealthCare!A16,Hospitalization!A16:K2358,9,TRUE) -> tier - 1
A17: Id16 | B17: =VLOOKUP(A17,'Customer Names'!A17:E1335,3,TRUE) -> Mr | C17: =VLOOKUP(A17,'Customer Names'!A15:E840,4,FALSE) -> Viau-Dupuis | D17: =VLOOKUP(HealthCare!A17,Medical_Examinations!A16:J2351,2,TRUE) -> 19.21 | E17: =VLOOKUP(HealthCare!A17,Medical_Examinations!A16:J2351,4,TRUE) -> 5.52 | F17: =VLOOKUP(A17,Medical_Examinations!A16:J2351,6,TRUE) -> No | G17: =VLOOKUP(A17,Medical_Examinations!A16:J2351,7,TRUE) -> No | H17: =VLOOKUP(A17,Medical_Examinations!A16:J2351,8,TRUE) -> No | I17: =VLOOKUP(A17,Medical_Examinations!A16:J2351,9,TRUE) -> 2 | J17: =VLOOKUP(A17,Medical_Examinations!A16:J2351,10,TRUE) -> No | K17: =VLOOKUP(A17,Medical_Examinations!A16:J2351,3,TRUE) -> Normal Weight | L17: =VLOOKUP(A17,Medical_Examinations!A16:J2351,5,TRUE) -> Normal | M17: =VLOOKUP(A17,Hospitalization!A17:K2359,5,FALSE) -> 25150 | N17: =VLOOKUP(A17,Hospitalization!A17:K2359,6,FALSE) -> 45 | O17: =VLOOKUP(A8,Hospitalization!A8:K2350,11,FALSE) -> R1012 | P17: =VLOOKUP(A17,Hospitalization!A17:K2359,10,TRUE) -> tier - 2 | Q17: =VLOOKUP(A17,Hospitalization!A17:K2359,8,TRUE) -> 14926.97 | R17: =VLOOKUP(HealthCare!A17,Hospitalization!A17:K2359,9,TRUE) -> tier - 2
A18: Id17 | B18: =VLOOKUP(A18,'Customer Names'!A18:E1336,3,TRUE) -> Ms | C18: =VLOOKUP(A18,'Customer Names'!A16:E841,4,FALSE) -> Cronin | D18: =VLOOKUP(HealthCare!A18,Medical_Examinations!A17:J2352,2,TRUE) -> 41.69 | E18: =VLOOKUP(HealthCare!A18,Medical_Examinations!A17:J2352,4,TRUE) -> 5.78 | F18: =VLOOKUP(A18,Medical_Examinations!A17:J2352,6,TRUE) -> No | G18: =VLOOKUP(A18,Medical_Examinations!A17:J2352,7,TRUE) -> No | H18: =VLOOKUP(A18,Medical_Examinations!A17:J2352,8,TRUE) -> No | I18: =VLOOKUP(A18,Medical_Examinations!A17:J2352,9,TRUE) -> 0 | J18: =VLOOKUP(A18,Medical_Examinations!A17:J2352,10,TRUE) -> No | K18: =VLOOKUP(A18,Medical_Examinations!A17:J2352,3,TRUE) -> Obesity | L18: =VLOOKUP(A18,Medical_Examinations!A17:J2352,5,TRUE) -> Prediabetes | M18: =VLOOKUP(A18,Hospitalization!A18:K2360,5,FALSE) -> 21893 | N18: =VLOOKUP(A18,Hospitalization!A18:K2360,6,FALSE) -> 46 | O18: =VLOOKUP(A9,Hospitalization!A9:K2351,11,FALSE) -> R1024 | P18: =VLOOKUP(A18,Hospitalization!A18:K2360,10,TRUE) -> tier - 3 | Q18: =VLOOKUP(A18,Hospitalization!A18:K2360,8,TRUE) -> 13390.56 | R18: =VLOOKUP(HealthCare!A18,Hospitalization!A18:K2360,9,TRUE) -> tier - 3
A19: Id18 | B19: =VLOOKUP(A19,'Customer Names'!A19:E1337,3,TRUE) -> Ms | C19: =VLOOKUP(A19,'Customer Names'!A17:E842,4,FALSE) -> Noordstar | D19: =VLOOKUP(HealthCare!A19,Medical_Examinations!A18:J2353,2,TRUE) -> 18.5 | E19: =VLOOKUP(HealthCare!A19,Medical_Examinations!A18:J2353,4,TRUE) -> 5.33 | F19: =VLOOKUP(A19,Medical_Examinations!A18:J2353,6,TRUE) -> No | G19: =VLOOKUP(A19,Medical_Examinations!A18:J2353,7,TRUE) -> No | H19: =VLOOKUP(A19,Medical_Examinations!A18:J2353,8,TRUE) -> No | I19: =VLOOKUP(A19,Medical_Examinations!A18:J2353,9,TRUE) -> 0 | J19: =VLOOKUP(A19,Medical_Examinations!A18:J2353,10,TRUE) -> No | K19: =VLOOKUP(A19,Medical_Examinations!A18:J2353,3,TRUE) -> Normal Weight | L19: =VLOOKUP(A19,Medical_Examinations!A18:J2353,5,TRUE) -> Normal | M19: =VLOOKUP(A19,Hospitalization!A19:K2361,5,FALSE) -> 23560 | N19: =VLOOKUP(A19,Hospitalization!A19:K2361,6,FALSE) -> 59 | O19: =VLOOKUP(A10,Hospitalization!A10:K2352,11,FALSE) -> R1013 | P19: =VLOOKUP(A19,Hospitalization!A19:K2361,10,TRUE) -> tier - 1 | Q19: =VLOOKUP(A19,Hospitalization!A19:K2361,8,TRUE) -> 12224.35 | R19: =VLOOKUP(HealthCare!A19,Hospitalization!A19:K2361,9,TRUE) -> tier - 3
A20: Id19 | B20: =VLOOKUP(A20,'Customer Names'!A20:E1338,3,TRUE) -> Ms | C20: =VLOOKUP(A20,'Customer Names'!A18:E843,4,FALSE) -> Boudalia | D20: =VLOOKUP(HealthCare!A20,Medical_Examinations!A19:J2354,2,TRUE) -> 21.24 | E20: =VLOOKUP(HealthCare!A20,Medical_Examinations!A19:J2354,4,TRUE) -> 4.49 | F20: =VLOOKUP(A20,Medical_Examinations!A19:J2354,6,TRUE) -> No | G20: =VLOOKUP(A20,Medical_Examinations!A19:J2354,7,TRUE) -> No | H20: =VLOOKUP(A20,Medical_Examinations!A19:J2354,8,TRUE) -> No | I20: =VLOOKUP(A20,Medical_Examinations!A19:J2354,9,TRUE) -> 0 | J20: =VLOOKUP(A20,Medical_Examinations!A19:J2354,10,TRUE) -> No | K20: =VLOOKUP(A20,Medical_Examinations!A19:J2354,3,TRUE) -> Normal Weight | L20: =VLOOKUP(A20,Medical_Examinations!A19:J2354,5,TRUE) -> Normal | M20: =VLOOKUP(A20,Hospitalization!A20:K2362,5,FALSE) -> 26293 | N20: =VLOOKUP(A20,Hospitalization!A20:K2362,6,FALSE) -> 53 | O20: =VLOOKUP(A11,Hospitalization!A2:K2344,11,TRUE) -> R1013 | P20: =VLOOKUP(A20,Hospitalization!A20:K2362,10,TRUE) -> tier - 1 | Q20: =VLOOKUP(A20,Hospitalization!A20:K2362,8,TRUE) -> 11265.71 | R20: =VLOOKUP(HealthCare!A20,Hospitalization!A20:K2362,9,TRUE) -> tier - 3
A21: Id20 | B21: =VLOOKUP(A21,'Customer Names'!A21:E1339,3,TRUE) -> Ms | C21: =VLOOKUP(A21,'Customer Names'!A19:E844,4,FALSE) -> Flor | D21: =VLOOKUP(HealthCare!A21,Medical_Examinations!A20:J2355,2,TRUE) -> 40.185 | E21: =VLOOKUP(HealthCare!A21,Medical_Examinations!A20:J2355,4,TRUE) -> 5.88 | F21: =VLOOKUP(A21,Medical_Examinations!A20:J2355,6,TRUE) -> yes | G21: =VLOOKUP(A21,Medical_Examinations!A20:J2355,7,TRUE) -> No | H21: =VLOOKUP(A21,Medical_Examinations!A20:J2355,8,TRUE) -> No | I21: =VLOOKUP(A21,Medical_Examinations!A20:J2355,9,TRUE) -> 0 | J21: =VLOOKUP(A21,Medical_Examinations!A20:J2355,10,TRUE) -> No | K21: =VLOOKUP(A21,Medical_Examinations!A20:J2355,3,TRUE) -> Obesity | L21: =VLOOKUP(A21,Medical_Examinations!A20:J2355,5,TRUE) -> Prediabetes | M21: =VLOOKUP(A21,Hospitalization!A21:K2363,5,FALSE) -> 25926 | N21: =VLOOKUP(A21,Hospitalization!A21:K2363,6,FALSE) -> 36 | O21: =VLOOKUP(A12,Hospitalization!A12:K2354,11,FALSE) -> R1011 | P21: =VLOOKUP(A21,Hospitalization!A21:K2363,10,TRUE) -> tier - 1 | Q21: =VLOOKUP(A21,Hospitalization!A21:K2363,8,TRUE) -> 10197.77 | R21: =VLOOKUP(HealthCare!A21,Hospitalization!A21:K2363,9,TRUE) -> tier - 3
A22: Id21 | B22: =VLOOKUP(A22,'Customer Names'!A22:E1340,3,TRUE) -> Ms | C22: =VLOOKUP(A22,'Customer Names'!A20:E845,4,FALSE) -> Fennon | D22: =VLOOKUP(HealthCare!A22,Medical_Examinations!A21:J2356,2,TRUE) -> 17.67 | E22: =VLOOKUP(HealthCare!A22,Medical_Examinations!A21:J2356,4,TRUE) -> 4.78 | F22: =VLOOKUP(A22,Medical_Examinations!A21:J2356,6,TRUE) -> No | G22: =VLOOKUP(A22,Medical_Examinations!A21:J2356,7,TRUE) -> No | H22: =VLOOKUP(A22,Medical_Examinations!A21:J2356,8,TRUE) -> No | I22: =VLOOKUP(A22,Medical_Examinations!A21:J2356,9,TRUE) -> 0 | J22: =VLOOKUP(A22,Medical_Examinations!A21:J2356,10,TRUE) -> No | K22: =VLOOKUP(A22,Medical_Examinations!A21:J2356,3,TRUE) -> Underweight | L22: =VLOOKUP(A22,Medical_Examinations!A21:J2356,5,TRUE) -> Normal | M22: =VLOOKUP(A22,Hospitalization!A22:K2364,5,FALSE) -> 27734 | N22: =VLOOKUP(A22,Hospitalization!A22:K2364,6,FALSE) -> 53 | O22: =VLOOKUP(A13,Hospitalization!A13:K2355,11,FALSE) -> R1011 | P22: =VLOOKUP(A22,Hospitalization!A22:K2364,10,TRUE) -> tier - 3 | Q22: =VLOOKUP(A22,Hospitalization!A22:K2364,8,TRUE) -> 9225.26 | R22: =VLOOKUP(HealthCare!A22,Hospitalization!A22:K2364,9,TRUE) -> tier - 3
A23: Id22 | B23: =VLOOKUP(A23,'Customer Names'!A23:E1341,3,TRUE) -> Mr | C23: =VLOOKUP(A23,'Customer Names'!A21:E846,4,FALSE) -> Hribar | D23: =VLOOKUP(HealthCare!A23,Medical_Examinations!A22:J2357,2,TRUE) -> 35.53 | E23: =VLOOKUP(HealthCare!A23,Medical_Examinations!A22:J2357,4,TRUE) -> 4.36 | F23: =VLOOKUP(A23,Medical_Examinations!A22:J2357,6,TRUE) -> No | G23: =VLOOKUP(A23,Medical_Examinations!A22:J2357,7,TRUE) -> No | H23: =VLOOKUP(A23,Medical_Examinations!A22:J2357,8,TRUE) -> Yes | I23: =VLOOKUP(A23,Medical_Examinations!A22:J2357,9,TRUE) -> 1 | J23: =VLOOKUP(A23,Medical_Examinations!A22:J2357,10,TRUE) -> No | K23: =VLOOKUP(A23,Medical_Examinations!A22:J2357,3,TRUE) -> Obesity | L23: =VLOOKUP(A23,Medical_Examinations!A22:J2357,5,TRUE) -> Normal | M23: =VLOOKUP(A23,Hospitalization!A23:K2365,5,FALSE) -> 30475 | N23: =VLOOKUP(A23,Hospitalization!A23:K2365,6,FALSE) -> 54 | O23: =VLOOKUP(A14,Hospitalization!A14:K2356,11,FALSE) -> R1011 | P23: =VLOOKUP(A23,Hospitalization!A23:K2365,10,TRUE) -> tier - 2 | Q23: =VLOOKUP(A23,Hospitalization!A23:K2365,8,TRUE) -> 8179.51 | R23: =VLOOKUP(HealthCare!A23,Hospitalization!A23:K2365,9,TRUE) -> tier - 2
A24: Id23 | B24: =VLOOKUP(A24,'Customer Names'!A24:E1342,3,TRUE) -> Ms | C24: =VLOOKUP(A24,'Customer Names'!A22:E847,4,FALSE) -> Tassello | D24: =VLOOKUP(HealthCare!A24,Medical_Examinations!A23:J2358,2,TRUE) -> 15.61 | E24: =VLOOKUP(HealthCare!A24,Medical_Examinations!A23:J2358,4,TRUE) -> 5.28 | F24: =VLOOKUP(A24,Medical_Examinations!A23:J2358,6,TRUE) -> No | G24: =VLOOKUP(A24,Medical_Examinations!A23:J2358,7,TRUE) -> No | H24: =VLOOKUP(A24,Medical_Examinations!A23:J2358,8,TRUE) -> No | I24: =VLOOKUP(A24,Medical_Examinations!A23:J2358,9,TRUE) -> 1 | J24: =VLOOKUP(A24,Medical_Examinations!A23:J2358,10,TRUE) -> No | K24: =VLOOKUP(A24,Medical_Examinations!A23:J2358,3,TRUE) -> Underweight | L24: =VLOOKUP(A24,Medical_Examinations!A23:J2358,5,TRUE) -> Normal | M24: =VLOOKUP(A24,Hospitalization!A24:K2366,5,FALSE) -> 29117 | N24: =VLOOKUP(A24,Hospitalization!A24:K2366,6,FALSE) -> 34 | O24: =VLOOKUP(A15,Hospitalization!A15:K2357,11,FALSE) -> R1018 | P24: =VLOOKUP(A24,Hospitalization!A24:K2366,10,TRUE) -> tier - 3 | Q24: =VLOOKUP(A24,Hospitalization!A24:K2366,8,TRUE) -> 7337.75 | R24: =VLOOKUP(HealthCare!A24,Hospitalization!A24:K2366,9,TRUE) -> tier - 2
A25: Id24 | B25: =VLOOKUP(A25,'Customer Names'!A25:E1343,3,TRUE) -> Ms | C25: =VLOOKUP(A25,'Customer Names'!A23:E848,4,FALSE) -> Mauricette | D25: =VLOOKUP(HealthCare!A25,Medical_Examinations!A24:J2359,2,TRUE) -> 17.58 | E25: =VLOOKUP(HealthCare!A25,Medical_Examinations!A24:J2359,4,TRUE) -> 4.51 | F25: =VLOOKUP(A25,Medical_Examinations!A24:J2359,6,TRUE) -> No | G25: =VLOOKUP(A25,Medical_Examinations!A24:J2359,7,TRUE) -> No | H25: =VLOOKUP(A25,Medical_Examinations!A24:J2359,8,TRUE) -> No | I25: =VLOOKUP(A25,Medical_Examinations!A24:J2359,9,TRUE) -> 1 | J25: =VLOOKUP(A25,Medical_Examinations!A24:J2359,10,TRUE) -> No | K25: =VLOOKUP(A25,Medical_Examinations!A24:J2359,3,TRUE) -> Underweight | L25: =VLOOKUP(A25,Medical_Examinations!A24:J2359,5,TRUE) -> Normal | M25: =VLOOKUP(A25,Hospitalization!A25:K2367,5,FALSE) -> 35001 | N25: =VLOOKUP(A25,Hospitalization!A25:K2367,6,FALSE) -> 61 | O25: =VLOOKUP(A16,Hospitalization!A16:K2358,11,FALSE) -> R1017 | P25: =VLOOKUP(A25,Hospitalization!A25:K2367,10,TRUE) -> tier - 3 | Q25: =VLOOKUP(A25,Hospitalization!A25:K2367,8,TRUE) -> 7042.11 | R25: =VLOOKUP(HealthCare!A25,Hospitalization!A25:K2367,9,TRUE) -> tier - 2
A26: Id25 | B26: =VLOOKUP(A26,'Customer Names'!A26:E1344,3,TRUE) -> Ms | C26: =VLOOKUP(A26,'Customer Names'!A24:E849,4,FALSE) -> Garcia | D26: =VLOOKUP(HealthCare!A26,Medical_Examinations!A25:J2360,2,TRUE) -> 17.58 | E26: =VLOOKUP(HealthCare!A26,Medical_Examinations!A25:J2360,4,TRUE) -> 4.51 | F26: =VLOOKUP(A26,Medical_Examinations!A25:J2360,6,TRUE) -> No | G26: =VLOOKUP(A26,Medical_Examinations!A25:J2360,7,TRUE) -> No | H26: =VLOOKUP(A26,Medical_Examinations!A25:J2360,8,TRUE) -> No | I26: =VLOOKUP(A26,Medical_Examinations!A25:J2360,9,TRUE) -> 1 | J26: =VLOOKUP(A26,Medical_Examinations!A25:J2360,10,TRUE) -> No | K26: =VLOOKUP(A26,Medical_Examinations!A25:J2360,3,TRUE) -> Underweight | L26: =VLOOKUP(A26,Medical_Examinations!A25:J2360,5,TRUE) -> Normal | M26: =VLOOKUP(A26,Hospitalization!A26:K2368,5,FALSE) -> 30930 | N26: =VLOOKUP(A26,Hospitalization!A26:K2368,6,FALSE) -> 38 | O26: =VLOOKUP(A17,Hospitalization!A17:K2359,11,FALSE) -> R1012 | P26: =VLOOKUP(A26,Hospitalization!A26:K2368,10,TRUE) -> tier - 3 | Q26: =VLOOKUP(A26,Hospitalization!A26:K2368,8,TRUE) -> 6933.24 | R26: =VLOOKUP(HealthCare!A26,Hospitalization!A26:K2368,9,TRUE) -> tier - 2
A27: Id26 | B27: =VLOOKUP(A27,'Customer Names'!A27:E1345,3,TRUE) -> Mr | C27: =VLOOKUP(A27,'Customer Names'!A25:E850,4,FALSE) -> Airoldi | D27: =VLOOKUP(HealthCare!A27,Medical_Examinations!A26:J2361,2,TRUE) -> 17.58 | E27: =VLOOKUP(HealthCare!A27,Medical_Examinations!A26:J2361,4,TRUE) -> 4.51 | F27: =VLOOKUP(A27,Medical_Examinations!A26:J2361,6,TRUE) -> No | G27: =VLOOKUP(A27,Medical_Examinations!A26:J2361,7,TRUE) -> No | H27: =VLOOKUP(A27,Medical_Examinations!A26:J2361,8,TRUE) -> No | I27: =VLOOKUP(A27,Medical_Examinations!A26:J2361,9,TRUE) -> 1 | J27: =VLOOKUP(A27,Medical_Examinations!A26:J2361,10,TRUE) -> No | K27: =VLOOKUP(A27,Medical_Examinations!A26:J2361,3,TRUE) -> Underweight | L27: =VLOOKUP(A27,Medical_Examinations!A26:J2361,5,TRUE) -> Normal | M27: =VLOOKUP(A27,Hospitalization!A27:K2369,5,FALSE) -> 29051 | N27: =VLOOKUP(A27,Hospitalization!A27:K2369,6,FALSE) -> 33 | O27: =VLOOKUP(A18,Hospitalization!A18:K2360,11,FALSE) -> R1011 | P27: =VLOOKUP(A27,Hospitalization!A27:K2369,10,TRUE) -> tier - 1 | Q27: =VLOOKUP(A27,Hospitalization!A27:K2369,8,TRUE) -> 6837.37 | R27: =VLOOKUP(HealthCare!A27,Hospitalization!A27:K2369,9,TRUE) -> tier - 3
A28: Id27 | B28: =VLOOKUP(A28,'Customer Names'!A28:E1346,3,TRUE) -> Mr | C28: =VLOOKUP(A28,'Customer Names'!A26:E851,4,FALSE) -> Cater-Cyker | D28: =VLOOKUP(HealthCare!A28,Medical_Examinations!A27:J2362,2,TRUE) -> 17.58 | E28: =VLOOKUP(HealthCare!A28,Medical_Examinations!A27:J2362,4,TRUE) -> 4.51 | F28: =VLOOKUP(A28,Medical_Examinations!A27:J2362,6,TRUE) -> No | G28: =VLOOKUP(A28,Medical_Examinations!A27:J2362,7,TRUE) -> No | H28: =VLOOKUP(A28,Medical_Examinations!A27:J2362,8,TRUE) -> No | I28: =VLOOKUP(A28,Medical_Examinations!A27:J2362,9,TRUE) -> 1 | J28: =VLOOKUP(A28,Medical_Examinations!A27:J2362,10,TRUE) -> No | K28: =VLOOKUP(A28,Medical_Examinations!A27:J2362,3,TRUE) -> Underweight | L28: =VLOOKUP(A28,Medical_Examinations!A27:J2362,5,TRUE) -> Normal | M28: =VLOOKUP(A28,Hospitalization!A28:K2370,5,FALSE) -> 25736 | N28: =VLOOKUP(A28,Hospitalization!A28:K2370,6,FALSE) -> 66 | O28: =VLOOKUP(A19,Hospitalization!A19:K2361,11,FALSE) -> R1012 | P28: =VLOOKUP(A28,Hospitalization!A28:K2370,10,TRUE) -> tier - 1 | Q28: =VLOOKUP(A28,Hospitalization!A28:K2370,8,TRUE) -> 6749.63 | R28: =VLOOKUP(HealthCare!A28,Hospitalization!A28:K2370,9,TRUE) -> tier - 2
A29: Id28 | B29: =VLOOKUP(A29,'Customer Names'!A29:E1347,3,TRUE) -> Ms | C29: =VLOOKUP(A29,'Customer Names'!A27:E852,4,FALSE) -> Hamm | D29: =VLOOKUP(HealthCare!A29,Medical_Examinations!A28:J2363,2,TRUE) -> 17.58 | E29: =VLOOKUP(HealthCare!A29,Medical_Examinations!A28:J2363,4,TRUE) -> 4.51 | F29: =VLOOKUP(A29,Medical_Examinations!A28:J2363,6,TRUE) -> No | G29: =VLOOKUP(A29,Medical_Examinations!A28:J2363,7,TRUE) -> No | H29: =VLOOKUP(A29,Medical_Examinations!A28:J2363,8,TRUE) -> No | I29: =VLOOKUP(A29,Medical_Examinations!A28:J2363,9,TRUE) -> 1 | J29: =VLOOKUP(A29,Medical_Examinations!A28:J2363,10,TRUE) -> No | K29: =VLOOKUP(A29,Medical_Examinations!A28:J2363,3,TRUE) -> Underweight | L29: =VLOOKUP(A29,Medical_Examinations!A28:J2363,5,TRUE) -> Normal | M29: =VLOOKUP(A29,Hospitalization!A29:K2371,5,FALSE) -> 29846 | N29: =VLOOKUP(A29,Hospitalization!A29:K2371,6,FALSE) -> 64 | O29: =VLOOKUP(A20,Hospitalization!A20:K2362,11,FALSE) -> R1025 | P29: =VLOOKUP(A29,Hospitalization!A29:K2371,10,TRUE) -> tier - 1 | Q29: =VLOOKUP(A29,Hospitalization!A29:K2371,8,TRUE) -> 6664.69 | R29: =VLOOKUP(HealthCare!A29,Hospitalization!A29:K2371,9,TRUE) -> tier - 3
A30: Id29 | B30: =VLOOKUP(A30,'Customer Names'!A30:E1348,3,TRUE) -> Mr | C30: =VLOOKUP(A30,'Customer Names'!A28:E853,4,FALSE) -> Cox | D30: =VLOOKUP(HealthCare!A30,Medical_Examinations!A29:J2364,2,TRUE) -> 17.58 | E30: =VLOOKUP(HealthCare!A30,Medical_Examinations!A29:J2364,4,TRUE) -> 4.51 | F30: =VLOOKUP(A30,Medical_Examinations!A29:J2364,6,TRUE) -> No | G30: =VLOOKUP(A30,Medical_Examinations!A29:J2364,7,TRUE) -> No | H30: =VLOOKUP(A30,Medical_Examinations!A29:J2364,8,TRUE) -> No | I30: =VLOOKUP(A30,Medical_Examinations!A29:J2364,9,TRUE) -> 1 | J30: =VLOOKUP(A30,Medical_Examinations!A29:J2364,10,TRUE) -> No | K30: =VLOOKUP(A30,Medical_Examinations!A29:J2364,3,TRUE) -> Underweight | L30: =VLOOKUP(A30,Medical_Examinations!A29:J2364,5,TRUE) -> Normal | M30: =VLOOKUP(A30,Hospitalization!A30:K2372,5,FALSE) -> 30314 | N30: =VLOOKUP(A30,Hospitalization!A30:K2372,6,FALSE) -> 65 | O30: =VLOOKUP(A21,Hospitalization!A21:K2363,11,FALSE) -> R1024 | P30: =VLOOKUP(A30,Hospitalization!A30:K2372,10,TRUE) -> tier - 2 | Q30: =VLOOKUP(A30,Hospitalization!A30:K2372,8,TRUE) -> 6600.21 | R30: =VLOOKUP(HealthCare!A30,Hospitalization!A30:K2372,9,TRUE) -> tier - 3
A31: Id30 | B31: =VLOOKUP(A31,'Customer Names'!A31:E1349,3,TRUE) -> Mr | C31: =VLOOKUP(A31,'Customer Names'!A29:E854,4,FALSE) -> Sachrajda | D31: =VLOOKUP(HealthCare!A31,Medical_Examinations!A30:J2365,2,TRUE) -> 17.58 | E31: =VLOOKUP(HealthCare!A31,Medical_Examinations!A30:J2365,4,TRUE) -> 4.51 | F31: =VLOOKUP(A31,Medical_Examinations!A30:J2365,6,TRUE) -> No | G31: =VLOOKUP(A31,Medical_Examinations!A30:J2365,7,TRUE) -> No | H31: =VLOOKUP(A31,Medical_Examinations!A30:J2365,8,TRUE) -> No | I31: =VLOOKUP(A31,Medical_Examinations!A30:J2365,9,TRUE) -> 1 | J31: =VLOOKUP(A31,Medical_Examinations!A30:J2365,10,TRUE) -> No | K31: =VLOOKUP(A31,Medical_Examinations!A30:J2365,3,TRUE) -> Underweight | L31: =VLOOKUP(A31,Medical_Examinations!A30:J2365,5,TRUE) -> Normal | M31: =VLOOKUP(A31,Hospitalization!A31:K2373,5,FALSE) -> 34522 | N31: =VLOOKUP(A31,Hospitalization!A31:K2373,6,FALSE) -> 36 | O31: =VLOOKUP(A22,Hospitalization!A22:K2364,11,FALSE) -> R1015 | P31: =VLOOKUP(A31,Hospitalization!A31:K2373,10,TRUE) -> tier - 1 | Q31: =VLOOKUP(A31,Hospitalization!A31:K2373,8,TRUE) -> 6512.24 | R31: =VLOOKUP(HealthCare!A31,Hospitalization!A31:K2373,9,TRUE) -> tier - 2
A32: Id31 | B32: =VLOOKUP(A32,'Customer Names'!A32:E1350,3,TRUE) -> Ms | C32: =VLOOKUP(A32,'Customer Names'!A30:E855,4,FALSE) -> Gareri | D32: =VLOOKUP(HealthCare!A32,Medical_Examinations!A31:J2366,2,TRUE) -> 17.58 | E32: =VLOOKUP(HealthCare!A32,Medical_Examinations!A31:J2366,4,TRUE) -> 4.51 | F32: =VLOOKUP(A32,Medical_Examinations!A31:J2366,6,TRUE) -> No | G32: =VLOOKUP(A32,Medical_Examinations!A31:J2366,7,TRUE) -> No | H32: =VLOOKUP(A32,Medical_Examinations!A31:J2366,8,TRUE) -> No | I32: =VLOOKUP(A32,Medical_Examinations!A31:J2366,9,TRUE) -> 1 | J32: =VLOOKUP(A32,Medical_Examinations!A31:J2366,10,TRUE) -> No | K32: =VLOOKUP(A32,Medical_Examinations!A31:J2366,3,TRUE) -> Underweight | L32: =VLOOKUP(A32,Medical_Examinations!A31:J2366,5,TRUE) -> Normal | M32: =VLOOKUP(A32,Hospitalization!A32:K2374,5,FALSE) -> 32024 | N32: =VLOOKUP(A32,Hospitalization!A32:K2374,6,FALSE) -> 59 | O32: =VLOOKUP(A23,Hospitalization!A23:K2365,11,FALSE) -> R1020 | P32: =VLOOKUP(A32,Hospitalization!A32:K2374,10,TRUE) -> tier - 2 | Q32: =VLOOKUP(A32,Hospitalization!A32:K2374,8,TRUE) -> 6414.18 | R32: =VLOOKUP(HealthCare!A32,Hospitalization!A32:K2374,9,TRUE) -> tier - 2
... A100: Id99 | B100: =VLOOKUP(A100,'Customer Names'!A100:E1418,3,TRUE) -> Ms | C100: =VLOOKUP(A100,'Customer Names'!A98:E923,4,FALSE) -> Gage | D100: =VLOOKUP(HealthCare!A100,Medical_Examinations!A99:J2434,2,TRUE) -> 17.58 | E100: =VLOOKUP(HealthCare!A100,Medical_Examinations!A99:J2434,4,TRUE) -> 4.51 | F100: =VLOOKUP(A100,Medical_Examinations!A99:J2434,6,TRUE) -> No | G100: =VLOOKUP(A100,Medical_Examinations!A99:J2434,7,TRUE) -> No | H100: =VLOOKUP(A100,Medical_Examinations!A99:J2434,8,TRUE) -> No | I100: =VLOOKUP(A100,Medical_Examinations!A99:J2434,9,TRUE) -> 1 | J100: =VLOOKUP(A100,Medical_Examinations!A99:J2434,10,TRUE) -> No | K100: =VLOOKUP(A100,Medical_Examinations!A99:J2434,3,TRUE) -> Underweight | L100: =VLOOKUP(A100,Medical_Examinations!A99:J2434,5,TRUE) -> Normal | M100: =VLOOKUP(A100,Hospitalization!A100:K2442,5,FALSE) -> 34148 | N100: =VLOOKUP(A100,Hospitalization!A100:K2442,6,FALSE) -> 67 | O100: =VLOOKUP(A91,Hospitalization!A91:K2433,11,FALSE) -> R1013 | P100: =VLOOKUP(A100,Hospitalization!A100:K2442,10,TRUE) -> tier - 3 | Q100: =VLOOKUP(A100,Hospitalization!A100:K2442,8,TRUE) -> 770 | R100: =VLOOKUP(HealthCare!A100,Hospitalization!A100:K2442,9,TRUE) -> tier - 3
A101: Id100 | B101: =VLOOKUP(A101,'Customer Names'!A101:E1419,3,TRUE) -> Mr | C101: =VLOOKUP(A101,'Customer Names'!A99:E924,4,FALSE) -> Gollins | D101: =VLOOKUP(HealthCare!A101,Medical_Examinations!A100:J2435,2,TRUE) -> 48.2 | E101: =VLOOKUP(HealthCare!A101,Medical_Examinations!A100:J2435,4,TRUE) -> 4.84 | F101: =VLOOKUP(A101,Medical_Examinations!A100:J2435,6,TRUE) -> No | G101: =VLOOKUP(A101,Medical_Examinations!A100:J2435,7,TRUE) -> No | H101: =VLOOKUP(A101,Medical_Examinations!A100:J2435,8,TRUE) -> No | I101: =VLOOKUP(A101,Medical_Examinations!A100:J2435,9,TRUE) -> 0 | J101: =VLOOKUP(A101,Medical_Examinations!A100:J2435,10,TRUE) -> yes | K101: =VLOOKUP(A101,Medical_Examinations!A100:J2435,3,TRUE) -> Obesity | L101: =VLOOKUP(A101,Medical_Examinations!A100:J2435,5,TRUE) -> Normal | M101: =VLOOKUP(A101,Hospitalization!A2:K2344,5,TRUE) -> 25822 | N101: =VLOOKUP(A101,Hospitalization!A2:K2344,6,TRUE) -> 34 | O101: =VLOOKUP(A92,Hospitalization!A92:K2434,11,FALSE) -> R1013 | P101: =VLOOKUP(A101,Hospitalization!A2:K2344,10,TRUE) -> tier - 1 | Q101: =VLOOKUP(A101,Hospitalization!A2:K2344,8,TRUE) -> 60021.4 | R101: =VLOOKUP(A101,Hospitalization!A2:K2344,9,TRUE) -> tier - 1
A102: Id101 | B102: =VLOOKUP(A102,'Customer Names'!A102:E1420,3,TRUE) -> Mr | C102: =VLOOKUP(A102,'Customer Names'!A100:E925,4,FALSE) -> Benestad | D102: =VLOOKUP(HealthCare!A102,Medical_Examinations!A101:J2436,2,TRUE) -> 35.75 | E102: =VLOOKUP(HealthCare!A102,Medical_Examinations!A101:J2436,4,TRUE) -> 8 | F102: =VLOOKUP(A102,Medical_Examinations!A101:J2436,6,TRUE) -> yes | G102: =VLOOKUP(A102,Medical_Examinations!A101:J2436,7,TRUE) -> No | H102: =VLOOKUP(A102,Medical_Examinations!A101:J2436,8,TRUE) -> No | I102: =VLOOKUP(A102,Medical_Examinations!A101:J2436,9,TRUE) -> 0 | J102: =VLOOKUP(A102,Medical_Examinations!A101:J2436,10,TRUE) -> yes | K102: =VLOOKUP(A102,Medical_Examinations!A101:J2436,3,TRUE) -> Obesity | L102: =VLOOKUP(A102,Medical_Examinations!A101:J2436,5,TRUE) -> Diabetes | M102: =VLOOKUP(A102,Hospitalization!A3:K2345,5,TRUE) -> 25173 | N102: =VLOOKUP(A102,Hospitalization!A3:K2345,6,TRUE) -> 24 | O102: =VLOOKUP(A93,Hospitalization!A93:K2435,11,FALSE) -> R1012 | P102: =VLOOKUP(A102,Hospitalization!A3:K2345,10,TRUE) -> tier - 3 | Q102: =VLOOKUP(A102,Hospitalization!A3:K2345,8,TRUE) -> 48549.18 | R102: =VLOOKUP(A102,Hospitalization!A3:K2345,9,TRUE) -> tier - 1
A103: Id102 | B103: =VLOOKUP(A103,'Customer Names'!A103:E1421,3,TRUE) -> Ms | C103: =VLOOKUP(A103,'Customer Names'!A101:E926,4,FALSE) -> Aviv | D103: =VLOOKUP(HealthCare!A103,Medical_Examinations!A102:J2437,2,TRUE) -> 53.81 | E103: =VLOOKUP(HealthCare!A103,Medical_Examinations!A102:J2437,4,TRUE) -> 8.77 | F103: =VLOOKUP(A103,Medical_Examinations!A102:J2437,6,TRUE) -> yes | G103: =VLOOKUP(A103,Medical_Examinations!A102:J2437,7,TRUE) -> No | H103: =VLOOKUP(A103,Medical_Examinations!A102:J2437,8,TRUE) -> No | I103: =VLOOKUP(A103,Medical_Examinations!A102:J2437,9,TRUE) -> 0 | J103: =VLOOKUP(A103,Medical_Examinations!A102:J2437,10,TRUE) -> yes | K103: =VLOOKUP(A103,Medical_Examinations!A102:J2437,3,TRUE) -> Obesity | L103: =VLOOKUP(A103,Medical_Examinations!A102:J2437,5,TRUE) -> Diabetes | M103: =VLOOKUP(A103,Hospitalization!A4:K2346,5,TRUE) -> 21745 | N103: =VLOOKUP(A103,Hospitalization!A4:K2346,6,TRUE) -> 25 | O103: =VLOOKUP(A94,Hospitalization!A94:K2436,11,FALSE) -> R1012 | P103: =VLOOKUP(A103,Hospitalization!A4:K2346,10,TRUE) -> tier - 1 | Q103: =VLOOKUP(A103,Hospitalization!A4:K2346,8,TRUE) -> 47055.53 | R103: =VLOOKUP(A103,Hospitalization!A4:K2346,9,TRUE) -> tier - 2
A104: Id103 | B104: =VLOOKUP(A104,'Customer Names'!A104:E1422,3,TRUE) -> Mr | C104: =VLOOKUP(A104,'Customer Names'!A102:E927,4,FALSE) -> Burns | D104: =VLOOKUP(HealthCare!A104,Medical_Examinations!A103:J2438,2,TRUE) -> 49.48 | E104: =VLOOKUP(HealthCare!A104,Medical_Examinations!A103:J2438,4,TRUE) -> 4.96 | F104: =VLOOKUP(A104,Medical_Examinations!A103:J2438,6,TRUE) -> No | G104: =VLOOKUP(A104,Medical_Examinations!A103:J2438,7,TRUE) -> No | H104: =VLOOKUP(A104,Medical_Examinations!A103:J2438,8,TRUE) -> Yes | I104: =VLOOKUP(A104,Medical_Examinations!A103:J2438,9,TRUE) -> 1 | J104: =VLOOKUP(A104,Medical_Examinations!A103:J2438,10,TRUE) -> yes | K104: =VLOOKUP(A104,Medical_Examinations!A103:J2438,3,TRUE) -> Obesity | L104: =VLOOKUP(A104,Medical_Examinations!A103:J2438,5,TRUE) -> Normal | M104: =VLOOKUP(A104,Hospitalization!A5:K2347,5,TRUE) -> 22271 | N104: =VLOOKUP(A104,Hospitalization!A5:K2347,6,TRUE) -> 29 | O104: =VLOOKUP(A95,Hospitalization!A95:K2437,11,FALSE) -> R1011 | P104: =VLOOKUP(A104,Hospitalization!A5:K2347,10,TRUE) -> tier - 2 | Q104: =VLOOKUP(A104,Hospitalization!A5:K2347,8,TRUE) -> 45710.21 | R104: =VLOOKUP(A104,Hospitalization!A5:K2347,9,TRUE) -> tier - 2
A105: Id104 | B105: =VLOOKUP(A105,'Customer Names'!A105:E1423,3,TRUE) -> Mr | C105: =VLOOKUP(A105,'Customer Names'!A103:E928,4,FALSE) -> Maldonado | D105: =VLOOKUP(HealthCare!A105,Medical_Examinations!A104:J2439,2,TRUE) -> 34.1 | E105: =VLOOKUP(HealthCare!A105,Medical_Examinations!A104:J2439,4,TRUE) -> 4.43 | F105: =VLOOKUP(A105,Medical_Examinations!A104:J2439,6,TRUE) -> yes | G105: =VLOOKUP(A105,Medical_Examinations!A104:J2439,7,TRUE) -> No | H105: =VLOOKUP(A105,Medical_Examinations!A104:J2439,8,TRUE) -> No | I105: =VLOOKUP(A105,Medical_Examinations!A104:J2439,9,TRUE) -> 0 | J105: =VLOOKUP(A105,Medical_Examinations!A104:J2439,10,TRUE) -> yes | K105: =VLOOKUP(A105,Medical_Examinations!A104:J2439,3,TRUE) -> Obesity | L105: =VLOOKUP(A105,Medical_Examinations!A104:J2439,5,TRUE) -> Normal | M105: =VLOOKUP(A105,Hospitalization!A6:K2348,5,TRUE) -> 24385 | N105: =VLOOKUP(A105,Hospitalization!A6:K2348,6,TRUE) -> 22 | O105: =VLOOKUP(A96,Hospitalization!A96:K2438,11,FALSE) -> R1013 | P105: =VLOOKUP(A105,Hospitalization!A6:K2348,10,TRUE) -> tier - 2 | Q105: =VLOOKUP(A105,Hospitalization!A6:K2348,8,TRUE) -> 43921.18 | R105: =VLOOKUP(A105,Hospitalization!A6:K2348,9,TRUE) -> tier - 2
